<mujoco model="base">
    <compiler angle="radian" meshdir="meshes/" />
    <option timestep="0.001" impratio="20" density="1.2" viscosity="2e-05" cone="elliptic" />
    <size njmax="5000" nconmax="5000" />
    <visual>
        <map znear="0.001" />
    </visual>
    <asset>
        <texture type="skybox" builtin="gradient" rgb1="0.9 0.9 1" rgb2="0.2 0.3 0.4" width="256" height="1536" />
        <texture type="2d" name="texplane" file="/home/haonan/Projects/Stowing/robosuite-1.2/robosuite/models/assets/arenas/../textures/wood-tiles.png" />
        <texture type="cube" name="tex-steel-brushed" file="/home/haonan/Projects/Stowing/robosuite-1.2/robosuite/models/assets/arenas/../textures/steel-brushed.png" />
        <texture type="2d" name="tex-cream-plaster" file="/home/haonan/Projects/Stowing/robosuite-1.2/robosuite/models/assets/arenas/../textures/cream-plaster.png" />
        <texture type="2d" name="tex-light-wood" file="/home/haonan/Projects/Stowing/robosuite-1.2/robosuite/models/assets/arenas/../textures/light-wood.png" />
        <texture type="2d" name="tex-dark-wood" file="/home/haonan/Projects/Stowing/robosuite-1.2/robosuite/models/assets/arenas/../textures/dark-wood.png" />
        <texture type="cube" name="tex-ceramic" file="/home/haonan/Projects/Stowing/robosuite-1.2/robosuite/models/assets/arenas/../textures/ceramic.png" />
        <material name="floorplane" texture="texplane" texuniform="true" texrepeat="2 2" specular="0" shininess="0" reflectance="0.01" />
        <material name="table_legs_metal" texture="tex-steel-brushed" shininess="0.8" reflectance="0.8" />
        <material name="walls_mat" texture="tex-cream-plaster" texuniform="true" texrepeat="3 3" specular="0.1" shininess="0.1" />
        <material name="light-wood" texture="tex-light-wood" texuniform="true" texrepeat="15 15" />
        <material name="dark-wood" texture="tex-dark-wood" texuniform="true" texrepeat="5 5" />
        <material name="table_ceramic" texture="tex-ceramic" specular="0.2" shininess="0" />
        <mesh name="robot0_base_link" file="/home/haonan/Projects/Stowing/robosuite-1.2/robosuite/models/assets/robots/kinova3/meshes/base_link.stl" />
        <mesh name="robot0_shoulder_link" file="/home/haonan/Projects/Stowing/robosuite-1.2/robosuite/models/assets/robots/kinova3/meshes/shoulder_link.stl" />
        <mesh name="robot0_half_arm_1_link" file="/home/haonan/Projects/Stowing/robosuite-1.2/robosuite/models/assets/robots/kinova3/meshes/half_arm_1_link.stl" />
        <mesh name="robot0_half_arm_2_link" file="/home/haonan/Projects/Stowing/robosuite-1.2/robosuite/models/assets/robots/kinova3/meshes/half_arm_2_link.stl" />
        <mesh name="robot0_forearm_link" file="/home/haonan/Projects/Stowing/robosuite-1.2/robosuite/models/assets/robots/kinova3/meshes/forearm_link.stl" />
        <mesh name="robot0_spherical_wrist_1_link" file="/home/haonan/Projects/Stowing/robosuite-1.2/robosuite/models/assets/robots/kinova3/meshes/spherical_wrist_1_link.stl" />
        <mesh name="robot0_spherical_wrist_2_link" file="/home/haonan/Projects/Stowing/robosuite-1.2/robosuite/models/assets/robots/kinova3/meshes/spherical_wrist_2_link.stl" />
        <mesh name="robot0_bracelet_with_vision_link" file="/home/haonan/Projects/Stowing/robosuite-1.2/robosuite/models/assets/robots/kinova3/meshes/bracelet_with_vision_link.stl" />
        <mesh name="mount0_pedestal" file="/home/haonan/Projects/Stowing/robosuite-1.2/robosuite/models/assets/mounts/meshes/rethink_mount/pedestal.stl" />
        <mesh name="gripper0_robotiq_arg2f_base_link" file="/home/haonan/Projects/Stowing/robosuite-1.2/robosuite/models/assets/grippers/meshes/robotiq_85_gripper/robotiq_arg2f_base_link.stl" />
        <mesh name="gripper0_robotiq_arg2f_85_outer_knuckle" file="/home/haonan/Projects/Stowing/robosuite-1.2/robosuite/models/assets/grippers/meshes/robotiq_85_gripper/robotiq_arg2f_85_outer_knuckle.stl" scale="0.001 0.001 0.001" />
        <mesh name="gripper0_robotiq_arg2f_85_outer_finger" file="/home/haonan/Projects/Stowing/robosuite-1.2/robosuite/models/assets/grippers/meshes/robotiq_85_gripper/robotiq_arg2f_85_outer_finger.stl" scale="0.001 0.001 0.001" />
        <mesh name="gripper0_robotiq_arg2f_85_inner_finger" file="/home/haonan/Projects/Stowing/robosuite-1.2/robosuite/models/assets/grippers/meshes/robotiq_85_gripper/robotiq_arg2f_85_inner_finger.stl" scale="0.001 0.001 0.001" />
        <mesh name="gripper0_robotiq_arg2f_85_inner_knuckle" file="/home/haonan/Projects/Stowing/robosuite-1.2/robosuite/models/assets/grippers/meshes/robotiq_85_gripper/robotiq_arg2f_85_inner_knuckle.stl" scale="0.001 0.001 0.001" />
        <mesh name="gripper0_robotiq_arg2f_85_outer_knuckle_vis" file="/home/haonan/Projects/Stowing/robosuite-1.2/robosuite/models/assets/grippers/meshes/robotiq_85_gripper/robotiq_arg2f_85_outer_knuckle_vis.stl" scale="0.001 0.001 0.001" />
        <mesh name="gripper0_robotiq_arg2f_85_outer_finger_vis" file="/home/haonan/Projects/Stowing/robosuite-1.2/robosuite/models/assets/grippers/meshes/robotiq_85_gripper/robotiq_arg2f_85_outer_finger_vis.stl" scale="0.001 0.001 0.001" />
        <mesh name="gripper0_robotiq_arg2f_85_inner_finger_vis" file="/home/haonan/Projects/Stowing/robosuite-1.2/robosuite/models/assets/grippers/meshes/robotiq_85_gripper/robotiq_arg2f_85_inner_finger_vis.stl" scale="0.001 0.001 0.001" />
        <mesh name="gripper0_robotiq_arg2f_85_inner_knuckle_vis" file="/home/haonan/Projects/Stowing/robosuite-1.2/robosuite/models/assets/grippers/meshes/robotiq_85_gripper/robotiq_arg2f_85_inner_knuckle_vis.stl" scale="0.001 0.001 0.001" />
    </asset>
    <worldbody>
        <geom name="floor" size="3 3 0.125" type="plane" group="1" material="floorplane" />
        <geom name="wall_leftcorner_visual" size="1.06 1.5 0.01" pos="-1.25 2.25 1.5" quat="0.653281 0.653281 0.270598 0.270598" type="box" contype="0" conaffinity="0" group="1" material="walls_mat" />
        <geom name="wall_rightcorner_visual" size="1.06 1.5 0.01" pos="-1.25 -2.25 1.5" quat="0.653281 0.653281 -0.270598 -0.270598" type="box" contype="0" conaffinity="0" group="1" material="walls_mat" />
        <geom name="wall_left_visual" size="1.75 1.5 0.01" pos="1.25 3 1.5" quat="0.707107 0.707107 0 0" type="box" contype="0" conaffinity="0" group="1" material="walls_mat" />
        <geom name="wall_right_visual" size="1.75 1.5 0.01" pos="1.25 -3 1.5" quat="0.707107 -0.707107 0 0" type="box" contype="0" conaffinity="0" group="1" material="walls_mat" />
        <geom name="wall_rear_visual" size="1.5 1.5 0.01" pos="-2 0 1.5" quat="0.5 0.5 0.5 0.5" type="box" contype="0" conaffinity="0" group="1" material="walls_mat" />
        <geom name="wall_front_visual" size="3 1.5 0.01" pos="3 0 1.5" quat="0.5 0.5 -0.5 -0.5" type="box" contype="0" conaffinity="0" group="1" material="walls_mat" />
        <camera name="frontview" pos="1.6 0 1.45" quat="0.56 0.43 0.43 0.56" />
        <camera name="birdview" pos="-0.2 0 3" quat="0.7071 0 0 0.7071" />
        <camera name="agentview" pos="1.5 0 2.45" quat="0.653 0.271 0.271 0.653" />
        <camera name="sideview" pos="-0.0565177 1.27612 1.48796" quat="0.00990507 0.00687796 0.591223 0.806418" />
        <camera name="cam_1" pos="-0.446758 0.343061 1.38088" quat="0.361777 0.223232 -0.463167 -0.777664" />
        <camera name="cam_2" pos="0.649045 0.51209 1.52376" quat="0.311384 0.127537 0.35117 0.873758" />
        <camera name="cam_3" pos="0.649045 -0.51209 1.52376" quat="0.77662 0.35538 0.0947273 0.511462" />
        <camera name="cam_4" pos="-0.61095 -0.498314 1.49445" quat="0.737274 0.362378 -0.275579 -0.499166" />
        <camera name="paper" pos="0.800697 -0.0894065 1.53966" quat="0.644019 0.282075 0.294035 0.647469" />
        <camera name="cam_slide" pos="0.648429 -0.0438354 1.33845" quat="0.664572 0.253708 0.242478 0.659683" />
        <camera name="cam_push" pos="0.0369926 -0.202781 1.38926" quat="0.707735 0.05461 0.0697688 0.700901" />
        <light pos="1 1 1.5" dir="-0.19245 -0.19245 -0.96225" directional="true" castshadow="false" />
        <body name="table" pos="0 0 0.4">
            <inertial pos="0 0 0" mass="768" diaginertia="81.92 133.12 133.12" />
            <geom name="table_collision" size="0.6 0.4 0.4" type="box" friction="0.3 0.005 0.0001" rgba="0.5 0.5 0 1" />
            <geom name="table_visual" size="0.6 0.4 0.4" type="box" contype="0" conaffinity="0" group="1" material="table_ceramic" />
            <geom name="table_leg1_visual" size="0.05 0.1" type="cylinder" contype="0" conaffinity="0" group="1" material="table_legs_metal" />
            <geom name="table_leg2_visual" size="0.05 0.1" type="cylinder" contype="0" conaffinity="0" group="1" material="table_legs_metal" />
            <geom name="table_leg3_visual" size="0.05 0.1" type="cylinder" contype="0" conaffinity="0" group="1" material="table_legs_metal" />
            <geom name="table_leg4_visual" size="0.05 0.1" type="cylinder" contype="0" conaffinity="0" group="1" material="table_legs_metal" />
            <site name="table_top" pos="0 0 0.4" size="0.001" rgba="0 0 0 0" />
        </body>
        <body name="shelf" pos="0.35 0 0.8">
            <inertial pos="0 0 0.0103908" quat="0.5 0.5 -0.5 0.5" mass="0.03355" diaginertia="0.000236023 0.00022753 7.88772e-05" />
            <geom name="shelf_bottom_collision" size="0.0625 0.140675 0.0005" type="box" rgba="0.5 0.5 0 1" />
            <geom name="shelf_bottom_visual" size="0.0625 0.140675 0.0005" type="box" contype="0" conaffinity="0" group="1" material="light-wood" />
            <geom name="shelf_right_collision" size="0.0625 5e-05 0.0835" pos="0 0.140725 0.0835" type="box" rgba="0.5 0.5 0 1" />
            <geom name="shelf_right_visual" size="0.0625 5e-05 0.0835" pos="0 0.140725 0.0835" type="box" contype="0" conaffinity="0" group="1" material="light-wood" />
            <geom name="shelf_left_collision" size="0.0625 5e-05 0.0835" pos="0 -0.140725 0.0835" type="box" rgba="0.5 0.5 0 1" />
            <geom name="shelf_left_visual" size="0.0625 5e-05 0.0835" pos="0 -0.140725 0.0835" type="box" contype="0" conaffinity="0" group="1" material="light-wood" />
        </body>
        <body name="box" pos="0.1 -0.2 1">
            <inertial pos="0 0 0" mass="3.6" diaginertia="0.03 0.03132 0.00732" />
            <joint type="free" />
            <geom size="0.06 0.05 0.15" type="box" rgba="0.5 0.5 0 1" />
        </body>
        <body name="robot0_base" pos="-0.46 0 0.912">
            <inertial pos="0 0 0" mass="0" diaginertia="0 0 0" />
            <geom name="robot0_g0_vis" type="mesh" contype="0" conaffinity="0" group="1" rgba="1 1 1 1" mesh="robot0_base_link" />
            <geom name="robot0_base_collision" type="mesh" conaffinity="0" rgba="0 0.5 0 1" mesh="robot0_base_link" />
            <camera name="robot0_robotview" pos="1 0 0.4" quat="0.653 0.271 0.271 0.653" />
            <body name="robot0_shoulder_link" pos="0 0 0.15643" quat="-3.67321e-06 1 0 0">
                <inertial pos="-2.3e-05 -0.010364 -0.07336" quat="0.707051 0.0451246 -0.0453544 0.704263" mass="1.3773" diaginertia="0.00488868 0.00457 0.00135132" />
                <joint name="robot0_Actuator1" pos="0 0 0" axis="0 0 1" armature="5" damping="0.1" frictionloss="0.1" />
                <geom name="robot0_s_visual" type="mesh" contype="0" conaffinity="0" group="1" rgba="1 1 1 1" mesh="robot0_shoulder_link" />
                <geom name="robot0_s_collision" type="mesh" conaffinity="0" rgba="0 0.5 0 1" mesh="robot0_shoulder_link" />
                <body name="robot0_HalfArm1_Link" pos="0 0.005375 -0.12838" quat="0.707105 0.707108 0 0">
                    <inertial pos="-4.4e-05 -0.09958 -0.013278" quat="0.482348 0.516286 -0.516862 0.483366" mass="1.1636" diaginertia="0.0113017 0.011088 0.00102532" />
                    <joint name="robot0_Actuator2" pos="0 0 0" axis="0 0 1" limited="true" range="-2.41 2.41" armature="2.5" damping="0.1" frictionloss="0.1" />
                    <geom name="robot0_ha1_visual" type="mesh" contype="0" conaffinity="0" group="1" rgba="1 1 1 1" mesh="robot0_half_arm_1_link" />
                    <geom name="robot0_ha1_collision" type="mesh" conaffinity="0" rgba="0 0.5 0 1" mesh="robot0_half_arm_1_link" />
                    <body name="robot0_HalfArm2_Link" pos="0 -0.21038 -0.006375" quat="0.707105 -0.707108 0 0">
                        <inertial pos="-4.4e-05 -0.006641 -0.117892" quat="0.706144 0.0213722 -0.0209128 0.707437" mass="1.1636" diaginertia="0.0111633 0.010932 0.00100671" />
                        <joint name="robot0_Actuator3" pos="0 0 0" axis="0 0 1" armature="1.66667" damping="0.1" frictionloss="0.1" />
                        <geom name="robot0_ha2_visual" type="mesh" contype="0" conaffinity="0" group="1" rgba="1 1 1 1" mesh="robot0_half_arm_2_link" />
                        <geom name="robot0_ha2_collision" type="mesh" conaffinity="0" rgba="0 0.5 0 1" mesh="robot0_half_arm_2_link" />
                        <body name="robot0_forearm_link" pos="0 0.006375 -0.21038" quat="0.707105 0.707108 0 0">
                            <inertial pos="-1.8e-05 -0.075478 -0.015006" quat="0.483678 0.515961 -0.515859 0.483455" mass="0.9302" diaginertia="0.00834839 0.008147 0.000598606" />
                            <joint name="robot0_Actuator4" pos="0 0 0" axis="0 0 1" limited="true" range="-2.66 2.66" armature="1.25" damping="0.1" frictionloss="0.1" />
                            <geom name="robot0_f_visual" type="mesh" contype="0" conaffinity="0" group="1" rgba="1 1 1 1" mesh="robot0_forearm_link" />
                            <geom name="robot0_f_collision" type="mesh" conaffinity="0" rgba="0 0.5 0 1" mesh="robot0_forearm_link" />
                            <body name="robot0_SphericalWrist1_Link" pos="0 -0.20843 -0.006375" quat="0.707105 -0.707108 0 0">
                                <inertial pos="1e-06 -0.009432 -0.063883" quat="0.703558 0.0707492 -0.0707492 0.703558" mass="0.6781" diaginertia="0.00165901 0.001596 0.000346988" />
                                <joint name="robot0_Actuator5" pos="0 0 0" axis="0 0 1" armature="1" damping="0.1" frictionloss="0.1" />
                                <geom name="robot0_w1_visual" type="mesh" contype="0" conaffinity="0" group="1" rgba="1 1 1 1" mesh="robot0_spherical_wrist_1_link" />
                                <geom name="robot0_w1_collision" type="mesh" conaffinity="0" rgba="0 0.5 0 1" mesh="robot0_spherical_wrist_1_link" />
                                <body name="robot0_SphericalWrist2_Link" pos="0 0.00017505 -0.10593" quat="0.707105 0.707108 0 0">
                                    <inertial pos="1e-06 -0.045483 -0.00965" quat="0.44426 0.550121 -0.550121 0.44426" mass="0.6781" diaginertia="0.00170087 0.001641 0.00035013" />
                                    <joint name="robot0_Actuator6" pos="0 0 0" axis="0 0 1" limited="true" range="-2.23 2.23" armature="0.833333" damping="0.01" frictionloss="0.1" />
                                    <geom name="robot0_w2_visual" type="mesh" contype="0" conaffinity="0" group="1" rgba="1 1 1 1" mesh="robot0_spherical_wrist_2_link" />
                                    <geom name="robot0_w2_collision" type="mesh" conaffinity="0" rgba="0 0.5 0 1" mesh="robot0_spherical_wrist_2_link" />
                                    <body name="robot0_Bracelet_Link" pos="0 -0.10593 -0.00017505" quat="0.707105 -0.707108 0 0">
                                        <inertial pos="-0.000281 -0.011402 -0.029798" quat="0.601961 0.40663 -0.381169 0.571843" mass="0.5006" diaginertia="0.000657515 0.000586793 0.000320693" />
                                        <joint name="robot0_Actuator7" pos="0 0 0" axis="0 0 1" armature="0.714286" damping="0.01" frictionloss="0.1" />
                                        <geom name="robot0_b_visual" type="mesh" contype="0" conaffinity="0" group="1" rgba="1 1 1 1" mesh="robot0_bracelet_with_vision_link" />
                                        <geom name="robot0_b_collision" type="mesh" conaffinity="0" rgba="0 0.5 0 1" mesh="robot0_bracelet_with_vision_link" />
                                        <body name="robot0_right_hand" pos="0 0 -0.065" quat="0 0.707105 -0.707108 0">
                                            <inertial pos="0 0 -0.065" quat="0 0.707105 -0.707108 0" mass="0" diaginertia="0 0 0" />
                                            <camera name="robot0_eye_in_hand" pos="0.05 0 0" quat="0 0.707108 0.707108 0" fovy="75" />
                                            <body name="gripper0_robotiq_85_adapter_link" pos="0 0 0">
                                                <inertial pos="0 0 0" mass="0.01" diaginertia="0.001 0.001 0.001" />
                                                <geom name="gripper0_hand_visual" type="mesh" contype="0" conaffinity="0" group="1" rgba="0.1 0.1 0.1 1" mesh="gripper0_robotiq_arg2f_base_link" />
                                                <geom name="gripper0_hand_collision" type="mesh" rgba="0 0 0.5 1" mesh="gripper0_robotiq_arg2f_base_link" />
                                                <site name="gripper0_ft_frame" pos="0 0 0" size="0.01" group="1" rgba="1 0 0 1" />
                                                <site name="gripper0_grip_site" pos="0 0 0.145" size="0.01" group="1" rgba="0.999998 1.81113e-06 0 0.5" />
                                                <site name="gripper0_grip_site_cylinder" pos="0 0 0.145" size="0.005 10" group="1" type="cylinder" rgba="0 1 0 0.3" />
                                                <body name="gripper0_left_outer_knuckle" pos="0 -0.0306011 0.054904" quat="0 0 0 1">
                                                    <inertial pos="0.000163875 0.0554825 -0.0100755" quat="0.920541 0.390623 -0.00362953 0.00231744" mass="0.0311462" diaginertia="5.11372e-05 4.89464e-05 4.95906e-06" />
                                                    <joint name="gripper0_finger_joint" pos="0 0 0" axis="1 0 0" limited="true" range="0 0.8" />
                                                    <geom name="gripper0_left_outer_knuckle_visual" type="mesh" contype="0" conaffinity="0" group="1" rgba="0.792157 0.819608 0.933333 1" mesh="gripper0_robotiq_arg2f_85_outer_knuckle_vis" />
                                                    <geom name="gripper0_left_outer_knuckle_collision" type="mesh" solref="0.01 0.25" rgba="0 0 0.5 1" mesh="gripper0_robotiq_arg2f_85_outer_knuckle" />
                                                    <geom name="gripper0_left_outer_finger_visual" pos="0 0.0315 -0.0041" type="mesh" contype="0" conaffinity="0" group="1" rgba="0.1 0.1 0.1 1" mesh="gripper0_robotiq_arg2f_85_outer_finger_vis" />
                                                    <geom name="gripper0_left_outer_finger_collision" pos="0 0.0315 -0.0041" type="mesh" solref="0.01 0.25" rgba="0 0 0.5 1" mesh="gripper0_robotiq_arg2f_85_outer_finger" />
                                                    <body name="gripper0_left_inner_finger" pos="0 0.0376 0.043">
                                                        <inertial pos="0.000199506 0.0032692 0.00175282" quat="0.933621 0.35825 -0.00273441 0.00104851" mass="0.0156391" diaginertia="1.57977e-05 1.51089e-05 1.4647e-06" />
                                                        <joint name="gripper0_left_inner_finger_joint" pos="0 0 0" axis="1 0 0" limited="true" range="-0.8757 0.8757" />
                                                        <geom name="gripper0_left_inner_finger_visual" type="mesh" contype="0" conaffinity="0" group="1" rgba="0.1 0.1 0.1 1" mesh="gripper0_robotiq_arg2f_85_inner_finger_vis" />
                                                        <geom name="gripper0_left_inner_finger_collision" type="mesh" solref="0.01 0.25" rgba="0 0 0.5 1" mesh="gripper0_robotiq_arg2f_85_inner_finger" />
                                                        <geom name="gripper0_left_fingertip_visual" size="0.011 0.003175 0.01875" pos="0 -0.0220203 0.03242" type="box" contype="0" conaffinity="0" group="1" rgba="0.9 0.9 0.9 1" />
                                                        <geom name="gripper0_left_fingertip_collision" size="0.011 0.003175 0.01875" pos="0 -0.0220203 0.03242" type="box" friction="2 2 2" solref="0.01 0.25" rgba="0 0 0.5 1" />
                                                        <geom name="gripper0_left_fingerpad_collision" size="0.01 0.001 0.01675" pos="0 -0.0245203 0.03242" type="box" friction="2 2 2" rgba="0 0 0.5 1" />
                                                    </body>
                                                </body>
                                                <body name="gripper0_left_inner_knuckle" pos="0 -0.0127 0.06142" quat="0 0 0 1">
                                                    <inertial pos="0.000123012 0.0507851 0.00103969" quat="0.497203 0.502496 -0.507943 0.492221" mass="0.0271177" diaginertia="2.83809e-05 2.61936e-05 2.81319e-06" />
                                                    <joint name="gripper0_left_inner_knuckle_joint" pos="0 0 0" axis="1 0 0" limited="true" range="0 0.8757" />
                                                    <geom name="gripper0_left_inner_knuckle_visual" type="mesh" contype="0" conaffinity="0" group="1" rgba="0.1 0.1 0.1 1" mesh="gripper0_robotiq_arg2f_85_inner_knuckle_vis" />
                                                    <geom name="gripper0_left_inner_knuckle_collision" type="mesh" rgba="0 0 0.5 1" mesh="gripper0_robotiq_arg2f_85_inner_knuckle" />
                                                </body>
                                                <body name="gripper0_right_outer_knuckle" pos="0 0.0306011 0.054904">
                                                    <inertial pos="0.000163875 0.0554825 -0.0100755" quat="0.920541 0.390623 -0.00362953 0.00231744" mass="0.0311462" diaginertia="5.11372e-05 4.89464e-05 4.95906e-06" />
                                                    <joint name="gripper0_right_outer_knuckle_joint" pos="0 0 0" axis="1 0 0" limited="true" range="0 0.8" />
                                                    <geom name="gripper0_right_outer_knuckle_visual" type="mesh" contype="0" conaffinity="0" group="1" rgba="0.792157 0.819608 0.933333 1" mesh="gripper0_robotiq_arg2f_85_outer_knuckle_vis" />
                                                    <geom name="gripper0_right_outer_knuckle_collision" type="mesh" solref="0.01 0.25" rgba="0 0 0.5 1" mesh="gripper0_robotiq_arg2f_85_outer_knuckle" />
                                                    <geom name="gripper0_right_outer_finger_visual" pos="0 0.0315 -0.0041" type="mesh" contype="0" conaffinity="0" group="1" rgba="0.1 0.1 0.1 1" mesh="gripper0_robotiq_arg2f_85_outer_finger_vis" />
                                                    <geom name="gripper0_right_outer_finger_collision" pos="0 0.0315 -0.0041" type="mesh" solref="0.01 0.25" rgba="0 0 0.5 1" mesh="gripper0_robotiq_arg2f_85_outer_finger" />
                                                    <body name="gripper0_right_inner_finger" pos="0 0.0376 0.043">
                                                        <inertial pos="0.000199506 0.0032692 0.00175282" quat="0.933621 0.35825 -0.00273441 0.00104851" mass="0.0156391" diaginertia="1.57977e-05 1.51089e-05 1.4647e-06" />
                                                        <joint name="gripper0_right_inner_finger_joint" pos="0 0 0" axis="1 0 0" limited="true" range="-0.8757 0.8757" />
                                                        <geom name="gripper0_right_inner_finger_visual" type="mesh" contype="0" conaffinity="0" group="1" rgba="0.1 0.1 0.1 1" mesh="gripper0_robotiq_arg2f_85_inner_finger_vis" />
                                                        <geom name="gripper0_right_inner_finger_collision" type="mesh" solref="0.01 0.25" rgba="0 0 0.5 1" mesh="gripper0_robotiq_arg2f_85_inner_finger" />
                                                        <geom name="gripper0_right_fingertip_visual" size="0.011 0.003175 0.01875" pos="0 -0.0220203 0.03242" type="box" contype="0" conaffinity="0" group="1" rgba="0.9 0.9 0.9 1" />
                                                        <geom name="gripper0_right_fingertip_collision" size="0.011 0.003175 0.01875" pos="0 -0.0220203 0.03242" type="box" friction="2 2 2" solref="0.01 0.25" rgba="0 0 0.5 1" />
                                                        <geom name="gripper0_right_fingerpad_collision" size="0.01 0.001 0.01675" pos="0 -0.0245203 0.03242" type="box" friction="2 2 2" rgba="0 0 0.5 1" />
                                                    </body>
                                                </body>
                                                <body name="gripper0_right_inner_knuckle" pos="0 0.0127 0.06142">
                                                    <inertial pos="0.000123012 0.0507851 0.00103969" quat="0.497203 0.502496 -0.507943 0.492221" mass="0.0271177" diaginertia="2.83809e-05 2.61936e-05 2.81319e-06" />
                                                    <joint name="gripper0_right_inner_knuckle_joint" pos="0 0 0" axis="1 0 0" limited="true" range="0 0.8757" />
                                                    <geom name="gripper0_right_inner_knuckle_visual" type="mesh" contype="0" conaffinity="0" group="1" rgba="0.1 0.1 0.1 1" mesh="gripper0_robotiq_arg2f_85_inner_knuckle_vis" />
                                                    <geom name="gripper0_right_inner_knuckle_collision" type="mesh" rgba="0 0 0.5 1" mesh="gripper0_robotiq_arg2f_85_inner_knuckle" />
                                                </body>
                                            </body>
                                        </body>
                                    </body>
                                </body>
                            </body>
                        </body>
                    </body>
                </body>
            </body>
            <body name="mount0_base" pos="0 0 0.01">
                <inertial pos="0 0 0.01" mass="0" diaginertia="0 0 0" />
                <body name="mount0_controller_box" pos="0 0 0">
                    <inertial pos="-0.325 0 -0.38" mass="46.64" diaginertia="1.71363 1.27988 0.809981" />
                    <geom name="mount0_controller_box_col" size="0.11 0.2 0.265" pos="-0.325 0 -0.38" type="box" rgba="0.5 0.5 0 1" />
                </body>
                <body name="mount0_pedestal_feet" pos="0 0 0">
                    <inertial pos="-0.1225 0 -0.758" mass="167.09" diaginertia="8.16095 9.59375 15.0785" />
                    <geom name="mount0_pedestal_feet_col" size="0.385 0.35 0.155" pos="-0.1225 0 -0.758" type="box" rgba="0.5 0.5 0 1" />
                </body>
                <body name="mount0_torso" pos="0 0 0">
                    <inertial pos="0 0 0" mass="0.0001" diaginertia="1e-08 1e-08 1e-08" />
                    <geom name="mount0_torso_vis" size="0.05 0.05 0.05" pos="0 0 -0.05" type="box" contype="0" conaffinity="0" group="1" rgba="0.2 0.2 0.2 1" />
                </body>
                <body name="mount0_pedestal" pos="0 0 0">
                    <inertial pos="0 0 0" quat="0.659267 -0.259505 -0.260945 0.655692" mass="60.864" diaginertia="6.0869 5.81635 4.20915" />
                    <geom name="mount0_pedestal_vis" type="mesh" contype="0" conaffinity="0" group="1" rgba="0.2 0.2 0.2 1" mesh="mount0_pedestal" />
                    <geom name="mount0_pedestal_col" size="0.18 0.31" pos="-0.02 0 -0.29" type="cylinder" rgba="0.5 0.5 0 1" />
                </body>
            </body>
        </body>
        <body name="cubeA_main" pos="0 0 0">
            <inertial pos="0 0 0" mass="0.064881" diaginertia="0.00047481 0.000155503 0.000620126" />
            <joint name="cubeA_joint0" type="free" />
            <geom name="cubeA_g0" size="0.083395 0.147374 0.0153462" type="box" friction="1.66434 0.005 0.0001" rgba="0.5 0 0 1" />
            <geom name="cubeA_g0_vis" size="0.083395 0.147374 0.0153462" type="box" contype="0" conaffinity="0" group="1" rgba="0.215686 0.494118 0.721569 1" />
            <site name="cubeA_default_site" pos="0 0 0" size="0.002" rgba="1 0 0 1" />
        </body>
        <body name="cubeB_0_main" pos="0 0 0">
            <inertial pos="0 0 0" mass="0.119647" diaginertia="0.00103166 0.00120674 0.000211571" />
            <joint name="cubeB_0_joint0" type="free" />
            <geom name="cubeB_0_g0" size="0.0696227 0.0213904 0.159405" type="box" friction="0.943524 0.005 0.0001" rgba="0.5 0 0 1" />
            <geom name="cubeB_0_g0_vis" size="0.0696227 0.0213904 0.159405" type="box" contype="0" conaffinity="0" group="1" rgba="0.301961 0.686275 0.290196 1" />
            <site name="cubeB_0_default_site" pos="0 0 0" size="0.002" rgba="1 0 0 1" />
        </body>
        <body name="cubeB_1_main" pos="0 0 0">
            <inertial pos="0 0 0" mass="0.153359" diaginertia="0.00112838 0.00157663 0.000495699" />
            <joint name="cubeB_1_joint0" type="free" />
            <geom name="cubeB_1_g0" size="0.0960875 0.0215422 0.147001" type="box" friction="0.609118 0.005 0.0001" rgba="0.5 0 0 1" />
            <geom name="cubeB_1_g0_vis" size="0.0960875 0.0215422 0.147001" type="box" contype="0" conaffinity="0" group="1" rgba="0.596078 0.305882 0.639216 1" />
            <site name="cubeB_1_default_site" pos="0 0 0" size="0.002" rgba="1 0 0 1" />
        </body>
        <body name="cubeB_2_main" pos="0 0 0">
            <inertial pos="0 0 0" mass="0.138457" diaginertia="0.00117178 0.00145501 0.000325596" />
            <joint name="cubeB_2_joint0" type="free" />
            <geom name="cubeB_2_g0" size="0.0812147 0.0214233 0.157894" type="box" friction="0.777744 0.005 0.0001" rgba="0.5 0 0 1" />
            <geom name="cubeB_2_g0_vis" size="0.0812147 0.0214233 0.157894" type="box" contype="0" conaffinity="0" group="1" rgba="1 0.498039 0 1" />
            <site name="cubeB_2_default_site" pos="0 0 0" size="0.002" rgba="1 0 0 1" />
        </body>
        <body name="cubeB_3_main" pos="0 0 0">
            <inertial pos="0 0 0" mass="0.14961" diaginertia="0.00113053 0.0014853 0.000406747" />
            <joint name="cubeB_3_joint0" type="free" />
            <geom name="cubeB_3_g0" size="0.0873788 0.0228273 0.148823" type="box" friction="0.791431 0.005 0.0001" rgba="0.5 0 0 1" />
            <geom name="cubeB_3_g0_vis" size="0.0873788 0.0228273 0.148823" type="box" contype="0" conaffinity="0" group="1" rgba="1 1 0.2 1" />
            <site name="cubeB_3_default_site" pos="0 0 0" size="0.002" rgba="1 0 0 1" />
        </body>
    </worldbody>
    <tendon>
        <fixed name="gripper0_finger2_12_cpl" range="-1 1" stiffness="0.4" springlength="0.001">
            <joint joint="gripper0_finger_joint" coef="1" />
            <joint joint="gripper0_left_inner_finger_joint" coef="-3" />
            <joint joint="gripper0_left_inner_knuckle_joint" coef="1" />
        </fixed>
        <fixed name="gripper0_finger1_12_cpl" range="-1 1" stiffness="0.4" springlength="0.001">
            <joint joint="gripper0_right_outer_knuckle_joint" coef="1" />
            <joint joint="gripper0_right_inner_finger_joint" coef="-3" />
            <joint joint="gripper0_right_inner_knuckle_joint" coef="1" />
        </fixed>
    </tendon>
    <actuator>
        <general name="robot0_torq_j1" joint="robot0_Actuator1" ctrllimited="true" ctrlrange="-32 32" />
        <general name="robot0_torq_j2" joint="robot0_Actuator2" ctrllimited="true" ctrlrange="-32 32" />
        <general name="robot0_torq_j3" joint="robot0_Actuator3" ctrllimited="true" ctrlrange="-32 32" />
        <general name="robot0_torq_j4" joint="robot0_Actuator4" ctrllimited="true" ctrlrange="-32 32" />
        <general name="robot0_torq_j5" joint="robot0_Actuator5" ctrllimited="true" ctrlrange="-32 32" />
        <general name="robot0_torq_j6" joint="robot0_Actuator6" ctrllimited="true" ctrlrange="-13 13" />
        <general name="robot0_torq_j7" joint="robot0_Actuator7" ctrllimited="true" ctrlrange="-13 13" />
        <general name="gripper0_finger_1" joint="gripper0_finger_joint" ctrllimited="true" ctrlrange="0 0.8" biastype="affine" gainprm="20 0 0 0 0 0 0 0 0 0" biasprm="0 -20 0 0 0 0 0 0 0 0" />
        <general name="gripper0_finger_2" joint="gripper0_right_outer_knuckle_joint" ctrllimited="true" ctrlrange="0 0.8" biastype="affine" gainprm="20 0 0 0 0 0 0 0 0 0" biasprm="0 -20 0 0 0 0 0 0 0 0" />
    </actuator>
    <sensor>
        <force site="gripper0_ft_frame" name="gripper0_force_ee" />
        <torque site="gripper0_ft_frame" name="gripper0_torque_ee" />
    </sensor>
</mujoco>
